<?xml version="1.0" ?>
<robot name="bigspot" xmlns:xacro="http://www.ros.org/wiki/xacro">

<xacro:include filename="$(find bigspot_description)/urdf/materials.xacro" />
<xacro:include filename="$(find bigspot_description)/urdf/bigspot.trans" />
<xacro:include filename="$(find bigspot_description)/urdf/bigspot.gazebo" />
<link name="base_link">
  <inertial>
    <origin xyz="-0.005924455452065034 -0.00013954843544972099 0.33234964114268223" rpy="0 0 0"/>
    <mass value="1.2002032804157028"/>
    <inertia ixx="0.003833" iyy="0.01767" izz="0.018171" ixy="-0.000152" iyz="-3.3e-05" ixz="-8e-05"/>
  </inertial>
  <visual>
    <origin xyz="0 0 0" rpy="0 0 0"/>
    <geometry>
      <mesh filename="package://bigspot_description/meshes/base_link.stl" scale="0.001 0.001 0.001"/>
    </geometry>
    <material name="silver"/>
  </visual>
  <collision>
    <origin xyz="0 0 0" rpy="0 0 0"/>
    <geometry>
      <mesh filename="package://bigspot_description/meshes/base_link.stl" scale="0.001 0.001 0.001"/>
    </geometry>
  </collision>
</link>

<link name="FRS_1">
  <inertial>
    <origin xyz="-0.03262402906297844 -0.008891213440249235 -0.01859885653575638" rpy="0 0 0"/>
    <mass value="0.2179660102657959"/>
    <inertia ixx="0.00014" iyy="0.000135" izz="9.7e-05" ixy="2e-06" iyz="-0.0" ixz="-3e-06"/>
  </inertial>
  <visual>
    <origin xyz="-0.152485 0.048774 -0.341762" rpy="0 0 0"/>
    <geometry>
      <mesh filename="package://bigspot_description/meshes/FRS_1.stl" scale="0.001 0.001 0.001"/>
    </geometry>
    <material name="silver"/>
  </visual>
  <collision>
    <origin xyz="-0.152485 0.048774 -0.341762" rpy="0 0 0"/>
    <geometry>
      <mesh filename="package://bigspot_description/meshes/FRS_1.stl" scale="0.001 0.001 0.001"/>
    </geometry>
  </collision>
</link>

<link name="FRL_1">
  <inertial>
    <origin xyz="0.0038775817781630667 -0.033503810432042994 -0.051270367340440826" rpy="0 0 0"/>
    <mass value="0.2533070021724165"/>
    <inertia ixx="0.000608" iyy="0.000566" izz="0.000103" ixy="4e-06" iyz="-3.8e-05" ixz="4e-05"/>
  </inertial>
  <visual>
    <origin xyz="-0.121434 0.09266 -0.322919" rpy="0 0 0"/>
    <geometry>
      <mesh filename="package://bigspot_description/meshes/FRL_1.stl" scale="0.001 0.001 0.001"/>
    </geometry>
    <material name="silver"/>
  </visual>
  <collision>
    <origin xyz="-0.121434 0.09266 -0.322919" rpy="0 0 0"/>
    <geometry>
      <mesh filename="package://bigspot_description/meshes/FRL_1.stl" scale="0.001 0.001 0.001"/>
    </geometry>
  </collision>
</link>

<link name="FRF_1">
  <inertial>
    <origin xyz="-0.001869412585041974 -0.03622957158869643 -0.04650897056843453" rpy="0 0 0"/>
    <mass value="0.25008271350190114"/>
    <inertia ixx="0.000701" iyy="0.000678" izz="7e-05" ixy="0.0" iyz="2e-06" ixz="9e-06"/>
  </inertial>
  <visual>
    <origin xyz="-0.145661 0.096431 -0.182302" rpy="0 0 0"/>
    <geometry>
      <mesh filename="package://bigspot_description/meshes/FRF_1.stl" scale="0.001 0.001 0.001"/>
    </geometry>
    <material name="silver"/>
  </visual>
  <collision>
    <origin xyz="-0.145661 0.096431 -0.182302" rpy="0 0 0"/>
    <geometry>
      <mesh filename="package://bigspot_description/meshes/FRF_1.stl" scale="0.001 0.001 0.001"/>
    </geometry>
  </collision>
</link>

<link name="FLS_1">
  <inertial>
    <origin xyz="-0.032502651385048306 0.008982081400929244 -0.01876110043924245" rpy="0 0 0"/>
    <mass value="0.2168042558568771"/>
    <inertia ixx="0.000138" iyy="0.000133" izz="9.6e-05" ixy="-1e-06" iyz="0.0" ixz="-4e-06"/>
  </inertial>
  <visual>
    <origin xyz="-0.152487 -0.049214 -0.341737" rpy="0 0 0"/>
    <geometry>
      <mesh filename="package://bigspot_description/meshes/FLS_1.stl" scale="0.001 0.001 0.001"/>
    </geometry>
    <material name="silver"/>
  </visual>
  <collision>
    <origin xyz="-0.152487 -0.049214 -0.341737" rpy="0 0 0"/>
    <geometry>
      <mesh filename="package://bigspot_description/meshes/FLS_1.stl" scale="0.001 0.001 0.001"/>
    </geometry>
  </collision>
</link>

<link name="FLL_1">
  <inertial>
    <origin xyz="0.0038795073898601623 0.033676971098066916 -0.0511565901145839" rpy="0 0 0"/>
    <mass value="0.2533070083934759"/>
    <inertia ixx="0.000608" iyy="0.000566" izz="0.000103" ixy="-4e-06" iyz="4e-05" ixz="4e-05"/>
  </inertial>
  <visual>
    <origin xyz="-0.12144 -0.092922 -0.323041" rpy="0 0 0"/>
    <geometry>
      <mesh filename="package://bigspot_description/meshes/FLL_1.stl" scale="0.001 0.001 0.001"/>
    </geometry>
    <material name="silver"/>
  </visual>
  <collision>
    <origin xyz="-0.12144 -0.092922 -0.323041" rpy="0 0 0"/>
    <geometry>
      <mesh filename="package://bigspot_description/meshes/FLL_1.stl" scale="0.001 0.001 0.001"/>
    </geometry>
  </collision>
</link>

<link name="FLF_1">
  <inertial>
    <origin xyz="-0.001867050204165388 0.036386780395052415 -0.04638544366195871" rpy="0 0 0"/>
    <mass value="0.25008282200400833"/>
    <inertia ixx="0.000701" iyy="0.000678" izz="7e-05" ixy="-0.0" iyz="-0.0" ixz="9e-06"/>
  </inertial>
  <visual>
    <origin xyz="-0.145667 -0.097168 -0.182437" rpy="0 0 0"/>
    <geometry>
      <mesh filename="package://bigspot_description/meshes/FLF_1.stl" scale="0.001 0.001 0.001"/>
    </geometry>
    <material name="silver"/>
  </visual>
  <collision>
    <origin xyz="-0.145667 -0.097168 -0.182437" rpy="0 0 0"/>
    <geometry>
      <mesh filename="package://bigspot_description/meshes/FLF_1.stl" scale="0.001 0.001 0.001"/>
    </geometry>
  </collision>
</link>

<link name="RRS_1">
  <inertial>
    <origin xyz="0.0327134074105363 -0.008946282789402397 -0.01858381030389067" rpy="0 0 0"/>
    <mass value="0.2178784733170752"/>
    <inertia ixx="0.000139" iyy="0.000135" izz="9.7e-05" ixy="-2e-06" iyz="-0.0" ixz="3e-06"/>
  </inertial>
  <visual>
    <origin xyz="0.164823 0.048791 -0.341723" rpy="0 0 0"/>
    <geometry>
      <mesh filename="package://bigspot_description/meshes/RRS_1.stl" scale="0.001 0.001 0.001"/>
    </geometry>
    <material name="silver"/>
  </visual>
  <collision>
    <origin xyz="0.164823 0.048791 -0.341723" rpy="0 0 0"/>
    <geometry>
      <mesh filename="package://bigspot_description/meshes/RRS_1.stl" scale="0.001 0.001 0.001"/>
    </geometry>
  </collision>
</link>

<link name="RRL_1">
  <inertial>
    <origin xyz="0.0005644107989059011 -0.03365254077769543 -0.05152345693558058" rpy="0 0 0"/>
    <mass value="0.25444871582041645"/>
    <inertia ixx="0.000615" iyy="0.000574" izz="0.000105" ixy="0.0" iyz="-4e-05" ixz="4.8e-05"/>
  </inertial>
  <visual>
    <origin xyz="0.133775 0.092485 -0.323" rpy="0 0 0"/>
    <geometry>
      <mesh filename="package://bigspot_description/meshes/RRL_1.stl" scale="0.001 0.001 0.001"/>
    </geometry>
    <material name="silver"/>
  </visual>
  <collision>
    <origin xyz="0.133775 0.092485 -0.323" rpy="0 0 0"/>
    <geometry>
      <mesh filename="package://bigspot_description/meshes/RRL_1.stl" scale="0.001 0.001 0.001"/>
    </geometry>
  </collision>
</link>

<link name="RRF_1">
  <inertial>
    <origin xyz="-0.0015923497064600778 -0.03624611498348912 -0.0465087745386944" rpy="0 0 0"/>
    <mass value="0.2500550328866579"/>
    <inertia ixx="0.0007" iyy="0.000678" izz="7e-05" ixy="1e-06" iyz="2e-06" ixz="1.1e-05"/>
  </inertial>
  <visual>
    <origin xyz="0.111933 0.096468 -0.181888" rpy="0 0 0"/>
    <geometry>
      <mesh filename="package://bigspot_description/meshes/RRF_1.stl" scale="0.001 0.001 0.001"/>
    </geometry>
    <material name="silver"/>
  </visual>
  <collision>
    <origin xyz="0.111933 0.096468 -0.181888" rpy="0 0 0"/>
    <geometry>
      <mesh filename="package://bigspot_description/meshes/RRF_1.stl" scale="0.001 0.001 0.001"/>
    </geometry>
  </collision>
</link>

<link name="RLS_1">
  <inertial>
    <origin xyz="0.03270821123980758 0.008996243250212595 -0.018554272527578353" rpy="0 0 0"/>
    <mass value="0.21782970948658575"/>
    <inertia ixx="0.000139" iyy="0.000135" izz="9.7e-05" ixy="2e-06" iyz="1e-06" ixz="3e-06"/>
  </inertial>
  <visual>
    <origin xyz="0.164822 -0.049198 -0.341698" rpy="0 0 0"/>
    <geometry>
      <mesh filename="package://bigspot_description/meshes/RLS_1.stl" scale="0.001 0.001 0.001"/>
    </geometry>
    <material name="silver"/>
  </visual>
  <collision>
    <origin xyz="0.164822 -0.049198 -0.341698" rpy="0 0 0"/>
    <geometry>
      <mesh filename="package://bigspot_description/meshes/RLS_1.stl" scale="0.001 0.001 0.001"/>
    </geometry>
  </collision>
</link>

<link name="RLL_1">
  <inertial>
    <origin xyz="0.0005648602121980373 0.03377765945377083 -0.051441442055425946" rpy="0 0 0"/>
    <mass value="0.254448653712132"/>
    <inertia ixx="0.000615" iyy="0.000574" izz="0.000105" ixy="-0.0" iyz="4.1e-05" ixz="4.8e-05"/>
  </inertial>
  <visual>
    <origin xyz="0.133774 -0.092964 -0.323081" rpy="0 0 0"/>
    <geometry>
      <mesh filename="package://bigspot_description/meshes/RLL_1.stl" scale="0.001 0.001 0.001"/>
    </geometry>
    <material name="silver"/>
  </visual>
  <collision>
    <origin xyz="0.133774 -0.092964 -0.323081" rpy="0 0 0"/>
    <geometry>
      <mesh filename="package://bigspot_description/meshes/RLL_1.stl" scale="0.001 0.001 0.001"/>
    </geometry>
  </collision>
</link>

<link name="RLF_1">
  <inertial>
    <origin xyz="-0.0015918551718841906 0.03635900100429153 -0.04642040795218652" rpy="0 0 0"/>
    <mass value="0.2500551183488915"/>
    <inertia ixx="0.0007" iyy="0.000678" izz="7e-05" ixy="-1e-06" iyz="-1e-06" ixz="1.1e-05"/>
  </inertial>
  <visual>
    <origin xyz="0.111932 -0.09729 -0.181979" rpy="0 0 0"/>
    <geometry>
      <mesh filename="package://bigspot_description/meshes/RLF_1.stl" scale="0.001 0.001 0.001"/>
    </geometry>
    <material name="silver"/>
  </visual>
  <collision>
    <origin xyz="0.111932 -0.09729 -0.181979" rpy="0 0 0"/>
    <geometry>
      <mesh filename="package://bigspot_description/meshes/RLF_1.stl" scale="0.001 0.001 0.001"/>
    </geometry>
  </collision>
</link>

<joint name="FRS_Joint" type="revolute">
  <origin xyz="0.152485 -0.048774 0.341762" rpy="0 0 0"/>
  <parent link="base_link"/>
  <child link="FRS_1"/>
  <axis xyz="-0.999998 3e-05 0.001745"/>
  <limit upper="0.523599" lower="-0.349066" effort="60.0" velocity="3"/>
</joint>

<joint name="FRL_Joint" type="revolute">
  <origin xyz="-0.031051 -0.043886 -0.018843" rpy="0 0 0"/>
  <parent link="FRS_1"/>
  <child link="FRL_1"/>
  <axis xyz="2.6e-05 0.999998 -0.002125"/>
  <limit upper="1.570796" lower="-1.570796" effort="60.0" velocity="3"/>
</joint>

<joint name="FRF_Joint" type="revolute">
  <origin xyz="0.024227 -0.003771 -0.140617" rpy="0 0 0"/>
  <parent link="FRL_1"/>
  <child link="FRF_1"/>
  <axis xyz="2.6e-05 0.999998 -0.002125"/>
  <limit upper="0.0" lower="-2.617994" effort="60.0" velocity="3"/>
</joint>

<joint name="FLS_Joint" type="revolute">
  <origin xyz="0.152487 0.049214 0.341737" rpy="0 0 0"/>
  <parent link="base_link"/>
  <child link="FLS_1"/>
  <axis xyz="-0.999998 3e-05 0.001745"/>
  <limit upper="0.349066" lower="-0.523599" effort="60.0" velocity="3"/>
</joint>

<joint name="FLL_Joint" type="revolute">
  <origin xyz="-0.031047 0.043708 -0.018696" rpy="0 0 0"/>
  <parent link="FLS_1"/>
  <child link="FLL_1"/>
  <axis xyz="3.9e-05 0.999985 0.005513"/>
  <limit upper="1.570796" lower="-1.570796" effort="60.0" velocity="3"/>
</joint>

<joint name="FLF_Joint" type="revolute">
  <origin xyz="0.024227 0.004246 -0.140604" rpy="0 0 0"/>
  <parent link="FLL_1"/>
  <child link="FLF_1"/>
  <axis xyz="-3.9e-05 -0.999985 -0.005513"/>
  <limit upper="2.617994" lower="0.0" effort="60.0" velocity="3"/>
</joint>

<joint name="RRS_Joint" type="revolute">
  <origin xyz="-0.164823 -0.048791 0.341723" rpy="0 0 0"/>
  <parent link="base_link"/>
  <child link="RRS_1"/>
  <axis xyz="-0.999998 7e-06 -0.001745"/>
  <limit upper="0.523599" lower="-0.349066" effort="60.0" velocity="3"/>
</joint>

<joint name="RRL_Joint" type="revolute">
  <origin xyz="0.031048 -0.043694 -0.018723" rpy="0 0 0"/>
  <parent link="RRS_1"/>
  <child link="RRL_1"/>
  <axis xyz="-1.5e-05 -0.999988 0.00488"/>
  <limit upper="1.570796" lower="-1.570796" effort="60.0" velocity="3"/>
</joint>

<joint name="RRF_Joint" type="revolute">
  <origin xyz="0.021842 -0.003983 -0.141112" rpy="0 0 0"/>
  <parent link="RRL_1"/>
  <child link="RRF_1"/>
  <axis xyz="-0.004077 0.999989 -0.002405"/>
  <limit upper="0.0" lower="-2.792527" effort="60.0" velocity="3"/>
</joint>

<joint name="RLS_Joint" type="revolute">
  <origin xyz="-0.164822 0.049198 0.341698" rpy="0 0 0"/>
  <parent link="base_link"/>
  <child link="RLS_1"/>
  <axis xyz="-0.999998 7e-06 -0.001745"/>
  <limit upper="0.349066" lower="-0.523599" effort="60.0" velocity="3"/>
</joint>

<joint name="RLL_Joint" type="revolute">
  <origin xyz="0.031048 0.043766 -0.018617" rpy="0 0 0"/>
  <parent link="RLS_1"/>
  <child link="RLL_1"/>
  <axis xyz="6e-06 -0.999973 -0.007312"/>
  <limit upper="1.570796" lower="-1.570796" effort="60.0" velocity="3"/>
</joint>

<joint name="RLF_Joint" type="revolute">
  <origin xyz="0.021842 0.004326 -0.141102" rpy="0 0 0"/>
  <parent link="RLL_1"/>
  <child link="RLF_1"/>
  <axis xyz="-0.004087 -0.99998 -0.004837"/>
  <limit upper="2.792527" lower="0.0" effort="60.0" velocity="3"/>
</joint>

</robot>
